Workbook

Sheet Keyword Database
A1: # | B1: Keyword | C1: Segment | D1: Buyer Type | E1: Intent | F1: Volume | G1: KD % | H1: CPC (USD) | I1: Opportunity Score | J1: Priority | K1: Cluster | L1: Status | M1: Notes
A2: 1 | B2: hyrox | C2: Hyrox | D2: Client | E2: Navigational | F2: 110000 | G2: 65 | H2: 0.53 | I2: =IF(G2="","",ROUND(F2*(100-G2)/100,0)) -> 38500 | J2: =IF(G2="","Needs KD",IF(D2<>"Client","Not a buyer",IF(AND(G2<=25,F2>=500),"P1 Quick Win",IF(AND(G2<=35,F2>=200),"P2 High Value",IF(G2<=50,"P3 Build","P4 Long Term"))))) -> P4 Long Term | K2: Fundamentals | L2: Not started
A3: 2 | B3: hyrox workout | C3: Hyrox | D3: Client | E3: Informational | F3: 22200 | G3: 46 | H3: 0.32 | I3: =IF(G3="","",ROUND(F3*(100-G3)/100,0)) -> 11988 | J3: =IF(G3="","Needs KD",IF(D3<>"Client","Not a buyer",IF(AND(G3<=25,F3>=500),"P1 Quick Win",IF(AND(G3<=35,F3>=200),"P2 High Value",IF(G3<=50,"P3 Build","P4 Long Term"))))) -> P3 Build | K3: Workouts | L3: Not started
A4: 3 | B4: hyrox london | C4: Hyrox | D4: Client | E4: Informational | F4: 18100 | G4: 26 | H4: 0.99 | I4: =IF(G4="","",ROUND(F4*(100-G4)/100,0)) -> 13394 | J4: =IF(G4="","Needs KD",IF(D4<>"Client","Not a buyer",IF(AND(G4<=25,F4>=500),"P1 Quick Win",IF(AND(G4<=35,F4>=200),"P2 High Value",IF(G4<=50,"P3 Build","P4 Long Term"))))) -> P2 High Value | K4: Race Events | L4: Not started
A5: 4 | B5: hyrox results | C5: Hyrox | D5: Client | E5: Informational | F5: 14800 | G5: 19 | H5: 2.63 | I5: =IF(G5="","",ROUND(F5*(100-G5)/100,0)) -> 11988 | J5: =IF(G5="","Needs KD",IF(D5<>"Client","Not a buyer",IF(AND(G5<=25,F5>=500),"P1 Quick Win",IF(AND(G5<=35,F5>=200),"P2 High Value",IF(G5<=50,"P3 Build","P4 Long Term"))))) -> P1 Quick Win | K5: Results & Data | L5: Not started
A6: 5 | B6: hyrox glasgow | C6: Hyrox | D6: Client | E6: Informational | F6: 6600 | G6: 17 | H6: 1.62 | I6: =IF(G6="","",ROUND(F6*(100-G6)/100,0)) -> 5478 | J6: =IF(G6="","Needs KD",IF(D6<>"Client","Not a buyer",IF(AND(G6<=25,F6>=500),"P1 Quick Win",IF(AND(G6<=35,F6>=200),"P2 High Value",IF(G6<=50,"P3 Build","P4 Long Term"))))) -> P1 Quick Win | K6: Race Events | L6: Not started
A7: 6 | B7: hyrox birmingham | C7: Hyrox | D7: Client | E7: Informational | F7: 6600 | G7: 30 | H7: 0 | I7: =IF(G7="","",ROUND(F7*(100-G7)/100,0)) -> 4620 | J7: =IF(G7="","Needs KD",IF(D7<>"Client","Not a buyer",IF(AND(G7<=25,F7>=500),"P1 Quick Win",IF(AND(G7<=35,F7>=200),"P2 High Value",IF(G7<=50,"P3 Build","P4 Long Term"))))) -> P2 High Value | K7: Race Events | L7: Not started
A8: 7 | B8: hyrox events | C8: Hyrox | D8: Client | E8: Informational | F8: 6600 | G8: 41 | H8: 1.54 | I8: =IF(G8="","",ROUND(F8*(100-G8)/100,0)) -> 3894 | J8: =IF(G8="","Needs KD",IF(D8<>"Client","Not a buyer",IF(AND(G8<=25,F8>=500),"P1 Quick Win",IF(AND(G8<=35,F8>=200),"P2 High Value",IF(G8<=50,"P3 Build","P4 Long Term"))))) -> P3 Build | K8: Race Events | L8: Not started
A9: 8 | B9: hyrox glasgow 2026 | C9: Hyrox | D9: Client | E9: Informational | F9: 5400 | G9: 16 | H9: 2 | I9: =IF(G9="","",ROUND(F9*(100-G9)/100,0)) -> 4536 | J9: =IF(G9="","Needs KD",IF(D9<>"Client","Not a buyer",IF(AND(G9<=25,F9>=500),"P1 Quick Win",IF(AND(G9<=35,F9>=200),"P2 High Value",IF(G9<=50,"P3 Build","P4 Long Term"))))) -> P1 Quick Win | K9: Race Events | L9: Not started
A10: 9 | B10: hyrox london 2025 | C10: Hyrox | D10: Client | E10: Informational | F10: 5400 | G10: 26 | H10: 0 | I10: =IF(G10="","",ROUND(F10*(100-G10)/100,0)) -> 3996 | J10: =IF(G10="","Needs KD",IF(D10<>"Client","Not a buyer",IF(AND(G10<=25,F10>=500),"P1 Quick Win",IF(AND(G10<=35,F10>=200),"P2 High Value",IF(G10<=50,"P3 Build","P4 Long Term"))))) -> P2 High Value | K10: Race Events | L10: Not started
A11: 10 | B11: what does hyrox stand for | C11: Hyrox | D11: Client | E11: Informational | F11: 5400 | G11: 28 | H11: 0.92 | I11: =IF(G11="","",ROUND(F11*(100-G11)/100,0)) -> 3888 | J11: =IF(G11="","Needs KD",IF(D11<>"Client","Not a buyer",IF(AND(G11<=25,F11>=500),"P1 Quick Win",IF(AND(G11<=35,F11>=200),"P2 High Value",IF(G11<=50,"P3 Build","P4 Long Term"))))) -> P2 High Value | K11: Fundamentals | L11: Not started
A12: 11 | B12: hyrox london 2026 | C12: Hyrox | D12: Client | E12: Informational | F12: 4400 | G12: 22 | H12: 1.17 | I12: =IF(G12="","",ROUND(F12*(100-G12)/100,0)) -> 3432 | J12: =IF(G12="","Needs KD",IF(D12<>"Client","Not a buyer",IF(AND(G12<=25,F12>=500),"P1 Quick Win",IF(AND(G12<=35,F12>=200),"P2 High Value",IF(G12<=50,"P3 Build","P4 Long Term"))))) -> P1 Quick Win | K12: Race Events | L12: Not started
A13: 12 | B13: hyrox dublin | C13: Hyrox | D13: Client | E13: Transactional | F13: 4400 | G13: 23 | H13: 0.41 | I13: =IF(G13="","",ROUND(F13*(100-G13)/100,0)) -> 3388 | J13: =IF(G13="","Needs KD",IF(D13<>"Client","Not a buyer",IF(AND(G13<=25,F13>=500),"P1 Quick Win",IF(AND(G13<=35,F13>=200),"P2 High Value",IF(G13<=50,"P3 Build","P4 Long Term"))))) -> P1 Quick Win | K13: Race Events | L13: Not started
... A219: 218 | B219: hyrox. | C219: Hyrox | D219: Client | E219: Navigational | F219: 110 | G219: 66 | H219: 0.53 | I219: =IF(G219="","",ROUND(F219*(100-G219)/100,0)) -> 37 | J219: =IF(G219="","Needs KD",IF(D219<>"Client","Not a buyer",IF(AND(G219<=25,F219>=500),"P1 Quick Win",IF(AND(G219<=35,F219>=200),"P2 High Value",IF(G219<=50,"P3 Build","P4 Long Term"))))) -> P4 Long Term | K219: Misspellings | L219: Not started
A220: 219 | B220: hyrox world championships results | C220: Hyrox | D220: Client | E220: Informational | F220: 90 | H220: 0 | I220: =IF(G220="","",ROUND(F220*(100-G220)/100,0)) | J220: =IF(G220="","Needs KD",IF(D220<>"Client","Not a buyer",IF(AND(G220<=25,F220>=500),"P1 Quick Win",IF(AND(G220<=35,F220>=200),"P2 High Value",IF(G220<=50,"P3 Build","P4 Long Term"))))) -> Needs KD | K220: Results & Data | L220: Not started
A221: 220 | B221: hyrox.glasgow | C221: Hyrox | D221: Client | E221: Informational | F221: 90 | G221: 9 | H221: 1.05 | I221: =IF(G221="","",ROUND(F221*(100-G221)/100,0)) -> 82 | J221: =IF(G221="","Needs KD",IF(D221<>"Client","Not a buyer",IF(AND(G221<=25,F221>=500),"P1 Quick Win",IF(AND(G221<=35,F221>=200),"P2 High Value",IF(G221<=50,"P3 Build","P4 Long Term"))))) -> P3 Build | K221: Race Events | L221: Not started
A222: 221 | B222: hyrox programmes | C222: Hyrox | D222: Client | E222: Commercial | F222: 90 | G222: 33 | H222: 1.24 | I222: =IF(G222="","",ROUND(F222*(100-G222)/100,0)) -> 60 | J222: =IF(G222="","Needs KD",IF(D222<>"Client","Not a buyer",IF(AND(G222<=25,F222>=500),"P1 Quick Win",IF(AND(G222<=35,F222>=200),"P2 High Value",IF(G222<=50,"P3 Build","P4 Long Term"))))) -> P3 Build | K222: Training Plans | L222: Not started
A223: 222 | B223: hyrox circuit workout | C223: Hyrox | D223: Client | E223: Informational | F223: 90 | G223: 55 | H223: 0.88 | I223: =IF(G223="","",ROUND(F223*(100-G223)/100,0)) -> 41 | J223: =IF(G223="","Needs KD",IF(D223<>"Client","Not a buyer",IF(AND(G223<=25,F223>=500),"P1 Quick Win",IF(AND(G223<=35,F223>=200),"P2 High Value",IF(G223<=50,"P3 Build","P4 Long Term"))))) -> P4 Long Term | K223: Workouts | L223: Not started
A224: 223 | B224: hyrox workout examples | C224: Hyrox | D224: Client | E224: Informational | F224: 90 | G224: 37 | H224: 0.57 | I224: =IF(G224="","",ROUND(F224*(100-G224)/100,0)) -> 57 | J224: =IF(G224="","Needs KD",IF(D224<>"Client","Not a buyer",IF(AND(G224<=25,F224>=500),"P1 Quick Win",IF(AND(G224<=35,F224>=200),"P2 High Value",IF(G224<=50,"P3 Build","P4 Long Term"))))) -> P3 Build | K224: Workouts | L224: Not started
A225: 224 | B225: what are the hyrox exercises | C225: Hyrox | D225: Client | E225: Informational | F225: 90 | G225: 38 | H225: 0.09 | I225: =IF(G225="","",ROUND(F225*(100-G225)/100,0)) -> 56 | J225: =IF(G225="","Needs KD",IF(D225<>"Client","Not a buyer",IF(AND(G225<=25,F225>=500),"P1 Quick Win",IF(AND(G225<=35,F225>=200),"P2 High Value",IF(G225<=50,"P3 Build","P4 Long Term"))))) -> P3 Build | K225: Workouts | L225: Not started
A226: 225 | B226: how does hyrox work | C226: Hyrox | D226: Client | E226: Informational | F226: 90 | G226: 52 | H226: 0.06 | I226: =IF(G226="","",ROUND(F226*(100-G226)/100,0)) -> 43 | J226: =IF(G226="","Needs KD",IF(D226<>"Client","Not a buyer",IF(AND(G226<=25,F226>=500),"P1 Quick Win",IF(AND(G226<=35,F226>=200),"P2 High Value",IF(G226<=50,"P3 Build","P4 Long Term"))))) -> P4 Long Term | K226: Fundamentals | L226: Not started
A227: 226 | B227: hyrox beginner training plan | C227: Hyrox | D227: Client | E227: Informational | F227: 90 | G227: 22 | H227: 0.68 | I227: =IF(G227="","",ROUND(F227*(100-G227)/100,0)) -> 70 | J227: =IF(G227="","Needs KD",IF(D227<>"Client","Not a buyer",IF(AND(G227<=25,F227>=500),"P1 Quick Win",IF(AND(G227<=35,F227>=200),"P2 High Value",IF(G227<=50,"P3 Build","P4 Long Term"))))) -> P3 Build | K227: Beginner | L227: Not started
A228: 227 | B228: hyrox beginner workouts | C228: Hyrox | D228: Client | E228: Informational | F228: 90 | G228: 35 | H228: 0.75 | I228: =IF(G228="","",ROUND(F228*(100-G228)/100,0)) -> 59 | J228: =IF(G228="","Needs KD",IF(D228<>"Client","Not a buyer",IF(AND(G228<=25,F228>=500),"P1 Quick Win",IF(AND(G228<=35,F228>=200),"P2 High Value",IF(G228<=50,"P3 Build","P4 Long Term"))))) -> P3 Build | K228: Beginner | L228: Not started
A229: 228 | B229: hyrox beginner | C229: Hyrox | D229: Client | E229: Informational | F229: 90 | G229: 45 | H229: 0.37 | I229: =IF(G229="","",ROUND(F229*(100-G229)/100,0)) -> 50 | J229: =IF(G229="","Needs KD",IF(D229<>"Client","Not a buyer",IF(AND(G229<=25,F229>=500),"P1 Quick Win",IF(AND(G229<=35,F229>=200),"P2 High Value",IF(G229<=50,"P3 Build","P4 Long Term"))))) -> P3 Build | K229: Beginner | L229: Not started
A230: 229 | B230: hyrox gym manchester | C230: Hyrox | D230: Facility | E230: Informational | F230: 90 | G230: 15 | H230: 0.9 | I230: =IF(G230="","",ROUND(F230*(100-G230)/100,0)) -> 77 | J230: =IF(G230="","Needs KD",IF(D230<>"Client","Not a buyer",IF(AND(G230<=25,F230>=500),"P1 Quick Win",IF(AND(G230<=35,F230>=200),"P2 High Value",IF(G230<=50,"P3 Build","P4 Long Term"))))) -> Not a buyer | K230: Coaching & Gyms | L230: Not started
A231: 230 | B231: hyrox app | C231: Hyrox | D231: Client | E231: Informational | F231: 90 | G231: 20 | H231: 1.96 | I231: =IF(G231="","",ROUND(F231*(100-G231)/100,0)) -> 72 | J231: =IF(G231="","Needs KD",IF(D231<>"Client","Not a buyer",IF(AND(G231<=25,F231>=500),"P1 Quick Win",IF(AND(G231<=35,F231>=200),"P2 High Value",IF(G231<=50,"P3 Build","P4 Long Term"))))) -> P3 Build | K231: Coaching & Gyms | L231: Not started
A232: 231 | B232: hyrox diet | C232: Hyrox | D232: Client | E232: Informational | F232: 90 | G232: 16 | H232: 0.53 | I232: =IF(G232="","",ROUND(F232*(100-G232)/100,0)) -> 76 | J232: =IF(G232="","Needs KD",IF(D232<>"Client","Not a buyer",IF(AND(G232<=25,F232>=500),"P1 Quick Win",IF(AND(G232<=35,F232>=200),"P2 High Value",IF(G232<=50,"P3 Build","P4 Long Term"))))) -> P3 Build | K232: Nutrition | L232: Not started
A233: 232 | B233: hyrox ranking | C233: Hyrox | D233: Client | E233: Informational | F233: 40 | H233: 2.32 | I233: =IF(G233="","",ROUND(F233*(100-G233)/100,0)) | J233: =IF(G233="","Needs KD",IF(D233<>"Client","Not a buyer",IF(AND(G233<=25,F233>=500),"P1 Quick Win",IF(AND(G233<=35,F233>=200),"P2 High Value",IF(G233<=50,"P3 Build","P4 Long Term"))))) -> Needs KD | K233: Results & Data | L233: Not started
A234: 233 | B234: hyrox paris results | C234: Hyrox | D234: Client | E234: Informational | F234: 30 | H234: 0 | I234: =IF(G234="","",ROUND(F234*(100-G234)/100,0)) | J234: =IF(G234="","Needs KD",IF(D234<>"Client","Not a buyer",IF(AND(G234<=25,F234>=500),"P1 Quick Win",IF(AND(G234<=35,F234>=200),"P2 High Value",IF(G234<=50,"P3 Build","P4 Long Term"))))) -> Needs KD | K234: Results & Data | L234: Not started
A235: 234 | B235: personal trainer jobs | C235: Personal Training | D235: Job Seeker | E235: Commercial | F235: 1900 | G235: 15 | H235: 1.63 | I235: =IF(G235="","",ROUND(F235*(100-G235)/100,0)) -> 1615 | J235: =IF(G235="","Needs KD",IF(D235<>"Client","Not a buyer",IF(AND(G235<=25,F235>=500),"P1 Quick Win",IF(AND(G235<=35,F235>=200),"P2 High Value",IF(G235<=50,"P3 Build","P4 Long Term"))))) -> Not a buyer | K235: PT Jobs | L235: Not started
A236: 235 | B236: personal fitness instructor jobs | C236: Personal Training | D236: Job Seeker | E236: Commercial | F236: 1600 | G236: 13 | H236: 1.32 | I236: =IF(G236="","",ROUND(F236*(100-G236)/100,0)) -> 1392 | J236: =IF(G236="","Needs KD",IF(D236<>"Client","Not a buyer",IF(AND(G236<=25,F236>=500),"P1 Quick Win",IF(AND(G236<=35,F236>=200),"P2 High Value",IF(G236<=50,"P3 Build","P4 Long Term"))))) -> Not a buyer | K236: PT Jobs | L236: Not started
A237: 236 | B237: how much is a personal trainer | C237: Personal Training | D237: Client | E237: Informational | F237: 1300 | G237: 12 | H237: 0.71 | I237: =IF(G237="","",ROUND(F237*(100-G237)/100,0)) -> 1144 | J237: =IF(G237="","Needs KD",IF(D237<>"Client","Not a buyer",IF(AND(G237<=25,F237>=500),"P1 Quick Win",IF(AND(G237<=35,F237>=200),"P2 High Value",IF(G237<=50,"P3 Build","P4 Long Term"))))) -> P1 Quick Win | K237: PT Pricing | L237: Not started
A238: 237 | B238: personal trainer manchester uk | C238: Personal Training | D238: Client | E238: Commercial | F238: 1000 | G238: 15 | H238: 3.46 | I238: =IF(G238="","",ROUND(F238*(100-G238)/100,0)) -> 850 | J238: =IF(G238="","Needs KD",IF(D238<>"Client","Not a buyer",IF(AND(G238<=25,F238>=500),"P1 Quick Win",IF(AND(G238<=35,F238>=200),"P2 High Value",IF(G238<=50,"P3 Build","P4 Long Term"))))) -> P1 Quick Win | K238: PT Location | L238: Not started
A239: 238 | B239: how much is a physical trainer | C239: Personal Training | D239: Client | E239: Informational | F239: 1000 | G239: 15 | H239: 0.71 | I239: =IF(G239="","",ROUND(F239*(100-G239)/100,0)) -> 850 | J239: =IF(G239="","Needs KD",IF(D239<>"Client","Not a buyer",IF(AND(G239<=25,F239>=500),"P1 Quick Win",IF(AND(G239<=35,F239>=200),"P2 High Value",IF(G239<=50,"P3 Build","P4 Long Term"))))) -> P1 Quick Win | K239: PT Pricing | L239: Not started
A240: 239 | B240: body conditioning class | C240: Personal Training | D240: Facility | E240: Informational | F240: 1000 | G240: 14 | H240: 1.03 | I240: =IF(G240="","",ROUND(F240*(100-G240)/100,0)) -> 860 | J240: =IF(G240="","Needs KD",IF(D240<>"Client","Not a buyer",IF(AND(G240<=25,F240>=500),"P1 Quick Win",IF(AND(G240<=35,F240>=200),"P2 High Value",IF(G240<=50,"P3 Build","P4 Long Term"))))) -> Not a buyer | K240: Classes | L240: Not started
A241: 240 | B241: personal trainer jobs near me | C241: Personal Training | D241: Job Seeker | E241: Commercial | F241: 1000 | G241: 15 | H241: 1.17 | I241: =IF(G241="","",ROUND(F241*(100-G241)/100,0)) -> 850 | J241: =IF(G241="","Needs KD",IF(D241<>"Client","Not a buyer",IF(AND(G241<=25,F241>=500),"P1 Quick Win",IF(AND(G241<=35,F241>=200),"P2 High Value",IF(G241<=50,"P3 Build","P4 Long Term"))))) -> Not a buyer | K241: PT Jobs | L241: Not started
A242: 241 | B242: personal fitness trainer jobs | C242: Personal Training | D242: Job Seeker | E242: Commercial | F242: 880 | G242: 15 | H242: 1.32 | I242: =IF(G242="","",ROUND(F242*(100-G242)/100,0)) -> 748 | J242: =IF(G242="","Needs KD",IF(D242<>"Client","Not a buyer",IF(AND(G242<=25,F242>=500),"P1 Quick Win",IF(AND(G242<=35,F242>=200),"P2 High Value",IF(G242<=50,"P3 Build","P4 Long Term"))))) -> Not a buyer | K242: PT Jobs | L242: Not started
A243: 242 | B243: personal fitness trainer jobs near me | C243: Personal Training | D243: Job Seeker | E243: Commercial | F243: 880 | G243: 12 | H243: 1.17 | I243: =IF(G243="","",ROUND(F243*(100-G243)/100,0)) -> 774 | J243: =IF(G243="","Needs KD",IF(D243<>"Client","Not a buyer",IF(AND(G243<=25,F243>=500),"P1 Quick Win",IF(AND(G243<=35,F243>=200),"P2 High Value",IF(G243<=50,"P3 Build","P4 Long Term"))))) -> Not a buyer | K243: PT Jobs | L243: Not started
A244: 243 | B244: personal trainer bristol | C244: Personal Training | D244: Client | E244: Commercial | F244: 590 | G244: 10 | H244: 1.03 | I244: =IF(G244="","",ROUND(F244*(100-G244)/100,0)) -> 531 | J244: =IF(G244="","Needs KD",IF(D244<>"Client","Not a buyer",IF(AND(G244<=25,F244>=500),"P1 Quick Win",IF(AND(G244<=35,F244>=200),"P2 High Value",IF(G244<=50,"P3 Build","P4 Long Term"))))) -> P1 Quick Win | K244: PT Location | L244: Not started
A245: 244 | B245: personal trainer vacancies london | C245: Personal Training | D245: Job Seeker | E245: Commercial | F245: 590 | G245: 14 | H245: 0.76 | I245: =IF(G245="","",ROUND(F245*(100-G245)/100,0)) -> 507 | J245: =IF(G245="","Needs KD",IF(D245<>"Client","Not a buyer",IF(AND(G245<=25,F245>=500),"P1 Quick Win",IF(AND(G245<=35,F245>=200),"P2 High Value",IF(G245<=50,"P3 Build","P4 Long Term"))))) -> Not a buyer | K245: PT Jobs | L245: Not started
...

Sheet Client Quick Wins
A1: THE BUILD LIST — buyer intent only, KD 30 or under, volume 200+
A2: Job-seeker, course-buyer and facility keywords are excluded. Those people will never buy coaching.
A4: Rank | B4: Keyword | C4: Segment | D4: Volume | E4: KD % | F4: CPC | G4: Opportunity | H4: Cluster
A5: 1 | B5: hyrox london | C5: Hyrox | D5: 18100 | E5: 26 | F5: 0.99 | G5: =ROUND(D5*(100-E5)/100,0) -> 13394 | H5: Race Events
A6: 2 | B6: hyrox results | C6: Hyrox | D6: 14800 | E6: 19 | F6: 2.63 | G6: =ROUND(D6*(100-E6)/100,0) -> 11988 | H6: Results & Data
A7: 3 | B7: hyrox glasgow | C7: Hyrox | D7: 6600 | E7: 17 | F7: 1.62 | G7: =ROUND(D7*(100-E7)/100,0) -> 5478 | H7: Race Events
A8: 4 | B8: hyrox birmingham | C8: Hyrox | D8: 6600 | E8: 30 | F8: 0 | G8: =ROUND(D8*(100-E8)/100,0) -> 4620 | H8: Race Events
A9: 5 | B9: hyrox glasgow 2026 | C9: Hyrox | D9: 5400 | E9: 16 | F9: 2 | G9: =ROUND(D9*(100-E9)/100,0) -> 4536 | H9: Race Events
A10: 6 | B10: hyrox london 2025 | C10: Hyrox | D10: 5400 | E10: 26 | F10: 0 | G10: =ROUND(D10*(100-E10)/100,0) -> 3996 | H10: Race Events
A11: 7 | B11: what does hyrox stand for | C11: Hyrox | D11: 5400 | E11: 28 | F11: 0.92 | G11: =ROUND(D11*(100-E11)/100,0) -> 3888 | H11: Fundamentals
A12: 8 | B12: hyrox london 2026 | C12: Hyrox | D12: 4400 | E12: 22 | F12: 1.17 | G12: =ROUND(D12*(100-E12)/100,0) -> 3432 | H12: Race Events
A13: 9 | B13: hyrox dublin | C13: Hyrox | D13: 4400 | E13: 23 | F13: 0.41 | G13: =ROUND(D13*(100-E13)/100,0) -> 3388 | H13: Race Events
A14: 10 | B14: hyrox birmingham 2025 | C14: Hyrox | D14: 4400 | E14: 23 | F14: 0 | G14: =ROUND(D14*(100-E14)/100,0) -> 3388 | H14: Race Events
A15: 11 | B15: hyrox trainers | C15: Hyrox | D15: 2900 | E15: 22 | F15: 0.68 | G15: =ROUND(D15*(100-E15)/100,0) -> 2262 | H15: Gear
A16: 12 | B16: hyrox stations | C16: Hyrox | D16: 2900 | E16: 29 | F16: 0.21 | G16: =ROUND(D16*(100-E16)/100,0) -> 2059 | H16: Stations & Rules
... A102: 98 | B102: is hyrox crossfit | C102: Hyrox | D102: 210 | E102: 28 | F102: 0 | G102: =ROUND(D102*(100-E102)/100,0) -> 151 | H102: Fundamentals

Sheet Buyer Intent Analysis
A1: WHO IS ACTUALLY SEARCHING?
A2: Low difficulty is not the same as low value. Much of the easiest volume in the PT set is people who want a JOB or a QUALIFICATION, not a coach.
A4: Buyer Type | B4: Keywords | C4: Total Volume | D4: Avg KD | E4: Avg CPC | F4: Worth Targeting?
A5: Client | B5: =COUNTIF('Keyword Database'!D:D,A5) -> 307 | C5: =SUMIF('Keyword Database'!D:D,A5,'Keyword Database'!F:F) -> 320110 | D5: =IFERROR(ROUND(SUMIF('Keyword Database'!D:D,A5,'Keyword Database'!G:G)/COUNTIF('Keyword Database'!D:D,A5),0),"") -> 26 | E5: =IFERROR(ROUND(SUMIF('Keyword Database'!D:D,A5,'Keyword Database'!H:H)/COUNTIF('Keyword Database'!D:D,A5),2),"") -> 0.65 | F5: YES - core business
A6: Job Seeker | B6: =COUNTIF('Keyword Database'!D:D,A6) -> 44 | C6: =SUMIF('Keyword Database'!D:D,A6,'Keyword Database'!F:F) -> 14550 | D6: =IFERROR(ROUND(SUMIF('Keyword Database'!D:D,A6,'Keyword Database'!G:G)/COUNTIF('Keyword Database'!D:D,A6),0),"") -> 13 | E6: =IFERROR(ROUND(SUMIF('Keyword Database'!D:D,A6,'Keyword Database'!H:H)/COUNTIF('Keyword Database'!D:D,A6),2),"") -> 1.14 | F6: NO - wants employment
A7: Course Buyer | B7: =COUNTIF('Keyword Database'!D:D,A7) -> 42 | C7: =SUMIF('Keyword Database'!D:D,A7,'Keyword Database'!F:F) -> 6580 | D7: =IFERROR(ROUND(SUMIF('Keyword Database'!D:D,A7,'Keyword Database'!G:G)/COUNTIF('Keyword Database'!D:D,A7),0),"") -> 12 | E7: =IFERROR(ROUND(SUMIF('Keyword Database'!D:D,A7,'Keyword Database'!H:H)/COUNTIF('Keyword Database'!D:D,A7),2),"") -> 5.59 | F7: MAYBE - affiliate only
A8: Facility | B8: =COUNTIF('Keyword Database'!D:D,A8) -> 26 | C8: =SUMIF('Keyword Database'!D:D,A8,'Keyword Database'!F:F) -> 9160 | D8: =IFERROR(ROUND(SUMIF('Keyword Database'!D:D,A8,'Keyword Database'!G:G)/COUNTIF('Keyword Database'!D:D,A8),0),"") -> 18 | E8: =IFERROR(ROUND(SUMIF('Keyword Database'!D:D,A8,'Keyword Database'!H:H)/COUNTIF('Keyword Database'!D:D,A8),2),"") -> 0.8 | F8: NO - wants a venue
A9: Partner | B9: =COUNTIF('Keyword Database'!D:D,A9) -> 2 | C9: =SUMIF('Keyword Database'!D:D,A9,'Keyword Database'!F:F) -> 250 | D9: =IFERROR(ROUND(SUMIF('Keyword Database'!D:D,A9,'Keyword Database'!G:G)/COUNTIF('Keyword Database'!D:D,A9),0),"") -> 22 | E9: =IFERROR(ROUND(SUMIF('Keyword Database'!D:D,A9,'Keyword Database'!H:H)/COUNTIF('Keyword Database'!D:D,A9),2),"") -> 0 | F9: MAYBE - gym partnerships
A10: Other | B10: =COUNTIF('Keyword Database'!D:D,A10) -> 4 | C10: =SUMIF('Keyword Database'!D:D,A10,'Keyword Database'!F:F) -> 1640 | D10: =IFERROR(ROUND(SUMIF('Keyword Database'!D:D,A10,'Keyword Database'!G:G)/COUNTIF('Keyword Database'!D:D,A10),0),"") -> 14 | E10: =IFERROR(ROUND(SUMIF('Keyword Database'!D:D,A10,'Keyword Database'!H:H)/COUNTIF('Keyword Database'!D:D,A10),2),"") -> 0 | F10: NO
A13: CLUSTER BREAKDOWN
A15: Cluster | B15: Segment | C15: Keywords | D15: Total Volume | E15: Avg KD | F15: Total Opportunity
A16: Beginner | B16: Hyrox | C16: =COUNTIF('Keyword Database'!K:K,A16) -> 8 | D16: =SUMIF('Keyword Database'!K:K,A16,'Keyword Database'!F:F) -> 980 | E16: =IFERROR(ROUND(SUMIF('Keyword Database'!K:K,A16,'Keyword Database'!G:G)/COUNTIF('Keyword Database'!K:K,A16),0),"") -> 28 | F16: =SUMIF('Keyword Database'!K:K,A16,'Keyword Database'!I:I) -> 716
A17: Brand/Nav | B17: Hyrox | C17: =COUNTIF('Keyword Database'!K:K,A17) -> 1 | D17: =SUMIF('Keyword Database'!K:K,A17,'Keyword Database'!F:F) -> 880 | E17: =IFERROR(ROUND(SUMIF('Keyword Database'!K:K,A17,'Keyword Database'!G:G)/COUNTIF('Keyword Database'!K:K,A17),0),"") -> 22 | F17: =SUMIF('Keyword Database'!K:K,A17,'Keyword Database'!I:I) -> 686
A18: Classes | B18: Personal Training | C18: =COUNTIF('Keyword Database'!K:K,A18) -> 16 | D18: =SUMIF('Keyword Database'!K:K,A18,'Keyword Database'!F:F) -> 4290 | E18: =IFERROR(ROUND(SUMIF('Keyword Database'!K:K,A18,'Keyword Database'!G:G)/COUNTIF('Keyword Database'!K:K,A18),0),"") -> 13 | F18: =SUMIF('Keyword Database'!K:K,A18,'Keyword Database'!I:I) -> 3750
A19: Coaching & Gyms | B19: Hyrox | C19: =COUNTIF('Keyword Database'!K:K,A19) -> 13 | D19: =SUMIF('Keyword Database'!K:K,A19,'Keyword Database'!F:F) -> 5580 | E19: =IFERROR(ROUND(SUMIF('Keyword Database'!K:K,A19,'Keyword Database'!G:G)/COUNTIF('Keyword Database'!K:K,A19),0),"") -> 22 | F19: =SUMIF('Keyword Database'!K:K,A19,'Keyword Database'!I:I) -> 4285
A20: Community | B20: Hyrox | C20: =COUNTIF('Keyword Database'!K:K,A20) -> 4 | D20: =SUMIF('Keyword Database'!K:K,A20,'Keyword Database'!F:F) -> 930 | E20: =IFERROR(ROUND(SUMIF('Keyword Database'!K:K,A20,'Keyword Database'!G:G)/COUNTIF('Keyword Database'!K:K,A20),0),"") -> 16 | F20: =SUMIF('Keyword Database'!K:K,A20,'Keyword Database'!I:I) -> 784
A21: Fundamentals | B21: Hyrox | C21: =COUNTIF('Keyword Database'!K:K,A21) -> 19 | D21: =SUMIF('Keyword Database'!K:K,A21,'Keyword Database'!F:F) -> 125390 | E21: =IFERROR(ROUND(SUMIF('Keyword Database'!K:K,A21,'Keyword Database'!G:G)/COUNTIF('Keyword Database'!K:K,A21),0),"") -> 46 | F21: =SUMIF('Keyword Database'!K:K,A21,'Keyword Database'!I:I) -> 47852
A22: Gear | B22: Hyrox | C22: =COUNTIF('Keyword Database'!K:K,A22) -> 12 | D22: =SUMIF('Keyword Database'!K:K,A22,'Keyword Database'!F:F) -> 8530 | E22: =IFERROR(ROUND(SUMIF('Keyword Database'!K:K,A22,'Keyword Database'!G:G)/COUNTIF('Keyword Database'!K:K,A22),0),"") -> 22 | F22: =SUMIF('Keyword Database'!K:K,A22,'Keyword Database'!I:I) -> 6683
A23: Misspellings | B23: Hyrox | C23: =COUNTIF('Keyword Database'!K:K,A23) -> 12 | D23: =SUMIF('Keyword Database'!K:K,A23,'Keyword Database'!F:F) -> 3100 | E23: =IFERROR(ROUND(SUMIF('Keyword Database'!K:K,A23,'Keyword Database'!G:G)/COUNTIF('Keyword Database'!K:K,A23),0),"") -> 58 | F23: =SUMIF('Keyword Database'!K:K,A23,'Keyword Database'!I:I) -> 1285
A24: Nutrition | B24: Hyrox | C24: =COUNTIF('Keyword Database'!K:K,A24) -> 1 | D24: =SUMIF('Keyword Database'!K:K,A24,'Keyword Database'!F:F) -> 90 | E24: =IFERROR(ROUND(SUMIF('Keyword Database'!K:K,A24,'Keyword Database'!G:G)/COUNTIF('Keyword Database'!K:K,A24),0),"") -> 16 | F24: =SUMIF('Keyword Database'!K:K,A24,'Keyword Database'!I:I) -> 76
A25: PT Courses | B25: Personal Training | C25: =COUNTIF('Keyword Database'!K:K,A25) -> 42 | D25: =SUMIF('Keyword Database'!K:K,A25,'Keyword Database'!F:F) -> 6580 | E25: =IFERROR(ROUND(SUMIF('Keyword Database'!K:K,A25,'Keyword Database'!G:G)/COUNTIF('Keyword Database'!K:K,A25),0),"") -> 12 | F25: =SUMIF('Keyword Database'!K:K,A25,'Keyword Database'!I:I) -> 5815
A26: PT Jobs | B26: Personal Training | C26: =COUNTIF('Keyword Database'!K:K,A26) -> 43 | D26: =SUMIF('Keyword Database'!K:K,A26,'Keyword Database'!F:F) -> 14440 | E26: =IFERROR(ROUND(SUMIF('Keyword Database'!K:K,A26,'Keyword Database'!G:G)/COUNTIF('Keyword Database'!K:K,A26),0),"") -> 13 | F26: =SUMIF('Keyword Database'!K:K,A26,'Keyword Database'!I:I) -> 12464
A27: PT Location | B27: Personal Training | C27: =COUNTIF('Keyword Database'!K:K,A27) -> 62 | D27: =SUMIF('Keyword Database'!K:K,A27,'Keyword Database'!F:F) -> 11580 | E27: =IFERROR(ROUND(SUMIF('Keyword Database'!K:K,A27,'Keyword Database'!G:G)/COUNTIF('Keyword Database'!K:K,A27),0),"") -> 12 | F27: =SUMIF('Keyword Database'!K:K,A27,'Keyword Database'!I:I) -> 10162
... A36: Workouts | B36: Hyrox | C36: =COUNTIF('Keyword Database'!K:K,A36) -> 29 | D36: =SUMIF('Keyword Database'!K:K,A36,'Keyword Database'!F:F) -> 29590 | E36: =IFERROR(ROUND(SUMIF('Keyword Database'!K:K,A36,'Keyword Database'!G:G)/COUNTIF('Keyword Database'!K:K,A36),0),"") -> 37 | F36: =SUMIF('Keyword Database'!K:K,A36,'Keyword Database'!I:I) -> 16796

Sheet Location Page Targets
A1: PT LOCATION PAGES — the town-by-town build
A2: Every one of these is client intent, KD 15 or under. This is the location layer, evidenced.
A4: Rank | B4: Keyword | C4: Volume | D4: KD % | E4: CPC | F4: Opportunity | G4: Suggested URL
A5: 1 | B5: personal trainer manchester uk | C5: 1000 | D5: 15 | E5: 3.46 | F5: =ROUND(C5*(100-D5)/100,0) -> 850 | G5: /online-personal-trainer/manchester
A6: 2 | B6: personal trainer bristol | C6: 590 | D6: 10 | E6: 1.03 | F6: =ROUND(C6*(100-D6)/100,0) -> 531 | G6: /online-personal-trainer/bristol
A7: 3 | B7: personal trainer bournemouth | C7: 390 | D7: 11 | E7: 0.93 | F7: =ROUND(C7*(100-D7)/100,0) -> 347 | G7: /online-personal-trainer/bournemouth
A8: 4 | B8: personal trainer northampton | C8: 320 | D8: 11 | E8: 1.14 | F8: =ROUND(C8*(100-D8)/100,0) -> 285 | G8: /online-personal-trainer/northampton
A9: 5 | B9: personal fitness trainer nottingham | C9: 320 | D9: 13 | E9: 0.99 | F9: =ROUND(C9*(100-D9)/100,0) -> 278 | G9: /online-personal-trainer/personal-nottingham
A10: 6 | B10: personal trainer brighton | C10: 320 | D10: 15 | E10: 1.29 | F10: =ROUND(C10*(100-D10)/100,0) -> 272 | G10: /online-personal-trainer/brighton
A11: 7 | B11: personal trainer cambridge | C11: 320 | D11: 15 | E11: 0.99 | F11: =ROUND(C11*(100-D11)/100,0) -> 272 | G11: /online-personal-trainer/cambridge
A12: 8 | B12: fitness trainer cardiff | C12: 320 | D12: 15 | E12: 1.02 | F12: =ROUND(C12*(100-D12)/100,0) -> 272 | G12: /online-personal-trainer/cardiff
A13: 9 | B13: personal trainer southampton | C13: 260 | D13: 12 | E13: 1.05 | F13: =ROUND(C13*(100-D13)/100,0) -> 229 | G13: /online-personal-trainer/southampton
A14: 10 | B14: personal trainer coventry uk | C14: 260 | D14: 13 | E14: 1.06 | F14: =ROUND(C14*(100-D14)/100,0) -> 226 | G14: /online-personal-trainer/coventry
A15: 11 | B15: personal trainer york | C15: 260 | D15: 14 | E15: 0.92 | F15: =ROUND(C15*(100-D15)/100,0) -> 224 | G15: /online-personal-trainer/york
A16: 12 | B16: personal trainers birmingham uk | C16: 210 | D16: 9 | E16: 0.87 | F16: =ROUND(C16*(100-D16)/100,0) -> 191 | G16: /online-personal-trainer/birmingham
... A66: 62 | B66: personal trainer prices london | C66: 90 | D66: 13 | E66: 1.23 | F66: =ROUND(C66*(100-D66)/100,0) -> 78 | G66: /online-personal-trainer/prices-london

Sheet Method & Legend
A1: SUV ATHLETIC — KEYWORD DATABASE v2
A3: SOURCE
A4: Batch 1 (Hyrox seed): 18 Semrush screenshots. Header totals 126,111 keywords / 624,610 volume / 34% avg KD.
A5: Batch 2 (Personal Training seed): 18 Semrush screenshots. Header totals 136,069 keywords / 2,223,300 volume / 42% avg KD.
A6: Combined addressable universe across both seeds: roughly 262,000 keywords and 2.85 million monthly searches.
A7: This workbook captures every keyword legible across those 36 screenshots.
A9: BUYER TYPE — THE MOST IMPORTANT COLUMN
A10: Client — wants to hire a coach or is researching the sport. These are customers. Target them.
A11: Job Seeker — wants a job in fitness (jobs, vacancies, careers, apprenticeships). Will never buy coaching.
A12: Course Buyer — wants to become a PT (courses, qualifications, salary questions). Not a customer, but CPC is very high
A13: ($4-10) because course providers bid hard. Only worth targeting as an affiliate revenue line, never as core content.
A14: Facility — wants a physical gym or class near them. An online coaching brand cannot serve this intent.
... A31: - the full location long tail - only ~65 UK towns appear here out of ~1,100 possible
